Workbook

Sheet dim_states
A1: State | B1: Region | C1: Safety | D1: Cost | E1: School | F1: composite school weighted | H1: Safety: Safe < 250, Moderate 250–450, Unsafe > 450 (VCR per 100k)
A2: Connecticut | B2: Northeast | C2: Safe | D2: Expensive | E2: Good | F2: 0.80465172
A3: Idaho | B3: West | C3: Safe | D3: Expensive | E3: Good | F3: 0.50183697 | H3: Cost: Cheap < $86,462, Expensive ≥ $86462
A4: Indiana | B4: Midwest | C4: Moderate | D4: Cheap | E4: Good | F4: 0.5207097
A5: Massachusetts | B5: Northeast | C5: Moderate | D5: Expensive | E5: Good | F5: 0.8303129 | H5: School: Good > 246, Weak ≤ 246
A6: Minnesota | B6: Midwest | C6: Moderate | D6: Expensive | E6: Good | F6: 0.52706167
A7: New Hampshire | B7: Northeast | C7: Safe | D7: Expensive | E7: Good | F7: 1.142454
A8: New Jersey | B8: Northeast | C8: Safe | D8: Expensive | E8: Good | F8: 0.88521587
A9: North Dakota | B9: Midwest | C9: Safe | D9: Cheap | E9: Good | F9: 0.54459612
A10: Utah | B10: West | C10: Safe | D10: Expensive | E10: Good | F10: 0.76340455
A11: Wisconsin | B11: Midwest | C11: Moderate | D11: Cheap | E11: Good | F11: 0.51718683
A12: Wyoming | B12: West | C12: Safe | D12: Cheap | E12: Good | F12: 0.89521124
A13: Kentucky | B13: South | C13: Safe | D13: Cheap | E13: Good | F13: 0.45829844
A14: Iowa | B14: Midwest | C14: Safe | D14: Cheap | E14: Good | F14: 0.44660403
A15: Ohio | B15: Midwest | C15: Moderate | D15: Cheap | E15: Good | F15: 0.42097538
A16: Nebraska | B16: Midwest | C16: Safe | D16: Cheap | E16: Good | F16: 0.41525092
A17: Pennsylvania | B17: Northeast | C17: Safe | D17: Cheap | E17: Good | F17: 0.38101623
... A51: New Mexico | B51: West | C51: Unsafe | D51: Cheap | E51: Weak | F51: -2.6206253

Sheet fact_costs
B1: house price | C1: mortgage monthly | D1: mortgage yearly | E1: utility monthly | F1: utility yearly | G1: groceries yearly | H1: 592 and roth | I1: cost to raise child | J1: cat yearly | K1: dog yearly | L1: home and expenses
A2: Alabama | B2: 219236 | C2: 1211.13 | D2: =C2*12 -> 14533.56 | E2: 542 | F2: =E2*12 -> 6504 | G2: =1398.02*12 -> 16776.24 | H2: 9600 | I2: =20550+H2 -> 30150 | J2: 1332 | K2: 1799 | L2: =G2+F2+D2+J2+K2+I2 -> 71094.8
A3: Alaska | B3: 358736 | C3: 1981.77 | D3: =C3*12 -> 23781.24 | E3: 647 | F3: =E3*12 -> 7764 | G3: =1839.5*12 -> 22074 | H3: 9600 | I3: =32947+H3 -> 42547 | J3: 1418 | K3: 1891 | L3: =G3+F3+D3+J3+K3+I3 -> 99475.24
A4: Arizona | B4: 406944 | C4: 2248.09 | D4: =C4*12 -> 26977.08 | E4: 495 | F4: =E4*12 -> 5940 | G4: =1486.32*12 -> 17835.84 | H4: 9600 | I4: 26624 | J4: 1339 | K4: 1812 | L4: =G4+F4+D4+J4+K4+I4 -> 80527.92
A5: Arkansas | B5: 223053 | C5: 1232.21 | D5: =C5*12 -> 14786.52 | E5: 502 | F5: =E5*12 -> 6024 | G5: =12*1398.02 -> 16776.24 | H5: 9600 | I5: =21840+H5 -> 31440 | J5: 1308 | K5: 1773 | L5: =G5+F5+D5+J5+K5+I5 -> 72107.76
A6: California | B6: 718104 | C6: 3967.03 | D6: =C6*12 -> 47604.36 | E6: 561 | F6: =E6*12 -> 6732 | G6: =1648.19*12 -> 19778.28 | H6: 9600 | I6: =35651+H6 -> 45251 | J6: 1418 | K6: 1891 | L6: =G6+F6+D6+J6+K6+I6 -> 122674.64
A7: Colorado | B7: 503084 | C7: 2779.19 | D7: =C7*12 -> 33350.28 | E7: 488 | F7: =E7*12 -> 5856 | G7: =1515.75*12 -> 18189 | H7: 9600 | I7: =34986+H7 -> 44586 | J7: 1356 | K7: 1826 | L7: =G7+F7+D7+J7+K7+I7 -> 105163.28
A8: Connecticut | B8: 367669 | C8: 2031.12 | D8: =C8*12 -> 24373.44 | E8: 554 | F8: =E8*12 -> 6648 | G8: =1545.18*12 -> 18542.16 | H8: 9600 | I8: =41808+H8 -> 51408 | J8: 1324 | K8: 1792 | L8: =G8+F8+D8+J8+K8+I8 -> 104087.6
A9: Delaware | B9: 328899 | C9: 1816.94 | D9: =C9*12 -> 21803.28 | E9: 570 | F9: =E9*12 -> 6840 | G9: =1501.03*12 -> 18012.36 | H9: 9600 | I9: =H9+24544 -> 34144 | J9: 1341 | K9: 1812 | L9: =G9+F9+D9+J9+K9+I9 -> 83952.64
A10: Florida | B10: 387663 | C10: 2141.57 | D10: =C10*12 -> 25698.84 | E10: 480 | F10: =E10*12 -> 5760 | G10: =1471.6*12 -> 17659.2 | H10: 9600 | I10: =H10+24045 -> 33645 | J10: 1356 | K10: 1827 | L10: =G10+F10+D10+J10+K10+I10 -> 85946.04
A11: Georgia | B11: 284809 | C11: 1573.37 | D11: =C11*12 -> 18880.44 | E11: 579 | F11: =E11*12 -> 6948 | G11: =1412.74*12 -> 16952.88 | H11: 9600 | I11: =H11+ 21299 -> 30899 | J11: 1352 | K11: 1820 | L11: =G11+F11+D11+J11+K11+I11 -> 76852.32
A12: Hawaii | B12: 886930 | C12: 4899.68 | D12: =C12*12 -> 58796.16 | E12: 616 | F12: =E12*12 -> 7392 | G12: =1913.08*12 -> 22956.96 | H12: 9600 | I12: =H12+ 33363 -> 42963 | J12: 1458 | K12: 1933 | L12: =G12+F12+D12+J12+K12+I12 -> 135499.12
A13: Idaho | B13: 417658 | C13: 2307.27 | D13: =C13*12 -> 27687.24 | E13: 553 | F13: =E13*12 -> 6636 | G13: =1456.88*12 -> 17482.56 | H13: 9600 | I13: =H13+ 24378 -> 33978 | J13: 1331 | K13: 1800 | L13: =G13+F13+D13+J13+K13+I13 -> 88914.8
A14: Illinois | B14: 251379 | C14: 1388.7 | D14: =C14*12 -> 16664.4 | E14: 457 | F14: =E14*12 -> 5484 | G14: =1471.6*12 -> 17659.2 | H14: 9600 | I14: 36806 | J14: 1371 | K14: 1841 | L14: =G14+F14+D14+J14+K14+I14 -> 79825.6
A15: Indiana | B15: 223999 | C15: 1237.44 | D15: =C15*12 -> 14849.28 | E15: 526 | F15: =E15*12 -> 6312 | G15: =1412.74*12 -> 16952.88 | H15: 9600 | I15: 37514 | J15: 1366 | K15: 1839 | L15: =G15+F15+D15+J15+K15+I15 -> 78833.16
A16: Iowa | B16: 212119 | C16: 1171.81 | D16: =C16*12 -> 14061.72 | E16: 460 | F16: =E16*12 -> 5520 | G16: =1442.17*12 -> 17306.04 | H16: 9600 | I16: 31773 | J16: 1337 | K16: 1806 | L16: =G16+F16+D16+J16+K16+I16 -> 71803.76
A17: Kansas | B17: 208892 | C17: 1153.98 | D17: =C17*12 -> 13847.76 | E17: 506 | F17: =E17*12 -> 6072 | G17: =1442.17*12 -> 17306.04 | H17: 9600 | I17: 31357 | J17: 1307 | K17: 1771 | L17: =G17+F17+D17+J17+K17+I17 -> 71660.8
A18: Kentucky | B18: 216986 | C18: 1198.7 | D18: =C18*12 -> 14384.4 | E18: 511 | F18: =E18*12 -> 6132 | G18: =1412.74*12 -> 16952.88 | H18: 9600 | I18: 30358 | J18: 1354 | K18: 1826 | L18: =G18+F18+D18+J18+K18+I18 -> 71007.28
A19: Louisiana | B19: 203886 | C19: 1126.33 | D19: =C19*12 -> 13515.96 | E19: 511 | F19: =E19*12 -> 6132 | G19: =1398.02*12 -> 16776.24 | H19: 9600 | I19: 31398 | J19: 1310 | K19: 1775 | L19: =G19+F19+D19+J19+K19+I19 -> 70907.2
A20: Maine | B20: 395378 | C20: 2184.19 | D20: =C20*12 -> 26210.28 | E20: 527 | F20: =E20*12 -> 6324 | G20: =1515.75*12 -> 18189 | H20: 9600 | I20: 38512 | J20: 1354 | K20: 1826 | L20: =G20+F20+D20+J20+K20+I20 -> 92415.28
A21: Maryland | B21: 359950 | C21: 1988.48 | D21: =C21*12 -> 23861.76 | E21: 561 | F21: =E21*12 -> 6732 | G21: =1515.75*12 -> 18189 | H21: 9600 | I21: 40883 | J21: 1389 | K21: 1861 | L21: =G21+F21+D21+J21+K21+I21 -> 92915.76
A22: Massachusetts | B22: 560849 | C22: 3098.3 | D22: =C22*12 -> 37179.6 | E22: 543 | F22: =E22*12 -> 6516 | G22: =1574.61*12 -> 18895.32 | H22: 9600 | I22: 53821 | J22: 1334 | K22: 1804 | L22: =G22+F22+D22+J22+K22+I22 -> 119549.92
A23: Michigan | B23: 234430 | C23: 1295.06 | D23: =C23*12 -> 15540.72 | E23: 472 | F23: =E23*12 -> 5664 | G23: =1427.45*12 -> 17129.4 | H23: 9600 | I23: 33187 | J23: 1339 | K23: 1810 | L23: =G23+F23+D23+J23+K23+I23 -> 74670.12
A24: Minnesota | B24: 312964 | C24: 1728.91 | D24: =C24*12 -> 20746.92 | E24: 451 | F24: =E24*12 -> 5412 | G24: =12*1486.32 -> 17835.84 | H24: 9600 | I24: 42797 | J24: 1361 | K24: 1831 | L24: =G24+F24+D24+J24+K24+I24 -> 89983.76
A25: Mississippi | B25: 184154 | C25: 1017.32 | D25: =C25*12 -> 12207.84 | E25: 517 | F25: =E25*12 -> 6204 | G25: =1398.02*12 -> 16776.24 | H25: 9600 | I25: 28778 | J25: 1329 | K25: 1795 | L25: =G25+F25+D25+J25+K25+I25 -> 67090.08
A26: Missouri | B26: 237568 | C26: 1312.4 | D26: =C26*12 -> 15748.8 | E26: 631 | F26: =E26*12 -> 7572 | G26: =1427.45*12 -> 17129.4 | H26: 9600 | I26: 35642 | J26: 1327 | K26: 1793 | L26: =G26+F26+D26+J26+K26+I26 -> 79212.2
A27: Montana | B27: 462337 | C27: 2554.09 | D27: =C27*12 -> 30649.08 | E27: 503 | F27: =E27*12 -> 6036 | G27: =1456.88*12 -> 17482.56 | H27: 9600 | I27: 38554 | J27: 1334 | K27: 1802 | L27: =G27+F27+D27+J27+K27+I27 -> 95857.64
A28: Nebraska | B28: 251933 | C28: 1391.76 | D28: =C28*12 -> 16701.12 | E28: 484 | F28: =E28*12 -> 5808 | G28: =1442.17*12 -> 17306.04 | H28: 9600 | I28: 35309 | J28: 1330 | K28: 1797 | L28: =G28+F28+D28+J28+K28+I28 -> 78251.16
A29: Nevada | B29: 405484 | C29: 2240.02 | D29: =C29*12 -> 26880.24 | E29: 430 | F29: =E29*12 -> 5160 | G29: =1501.03*12 -> 18012.36 | H29: 9600 | I29: 36723 | J29: 1336 | K29: 1805 | L29: =G29+F29+D29+J29+K29+I29 -> 89916.6
A30: New Hampshire | B30: 463093 | C30: 2558.27 | D30: =C30*12 -> 30699.24 | E30: 525 | F30: =E30*12 -> 6300 | G30: =1515.75*12 -> 18189 | H30: 9600 | I30: 42339 | J30: 1318 | K30: 1786 | L30: =G30+F30+D30+J30+K30+I30 -> 100631.24
A31: New Jersey | B31: 472215 | C31: 2608.66 | D31: =C31*12 -> 31303.92 | E31: 613 | F31: =E31*12 -> 7356 | G31: =1530.46*12 -> 18365.52 | H31: 9600 | I31: 44669 | J31: 1408 | K31: 1882 | L31: =G31+F31+D31+J31+K31+I31 -> 104984.44
A32: New Mexico | B32: 306366 | C32: 1692.46 | D32: =C32*12 -> 20309.52 | E32: 384 | F32: =E32*12 -> 4608 | G32: =1412.74*12 -> 16952.88 | H32: 9600 | I32: 34810 | J32: 1335 | K32: 1803 | L32: =G32+F32+D32+J32+K32+I32 -> 79818.4
A33: New York | B33: 318382 | C33: 1758.84 | D33: =C33*12 -> 21106.08 | E33: 535 | F33: =E33*12 -> 6420 | G33: =1501.03*12 -> 18012.36 | H33: 9600 | I33: 42880 | J33: 1430 | K33: 1905 | L33: =G33+F33+D33+J33+K33+I33 -> 91753.44
A34: North Carolina | B34: 304948 | C34: 1684.63 | D34: =C34*12 -> 20215.56 | E34: 493 | F34: =E34*12 -> 5916 | G34: =1412.74*12 -> 16952.88 | H34: 9600 | I34: 33187 | J34: 1337 | K34: 1805 | L34: =G34+F34+D34+J34+K34+I34 -> 79413.44
A35: North Dakota | B35: 246697 | C35: 1362.83 | D35: =C35*12 -> 16353.96 | E35: 443 | F35: =E35*12 -> 5316 | G35: =1442.17*12 -> 17306.04 | H35: 9600 | I35: 34352 | J35: 1303 | K35: 1766 | L35: =G35+F35+D35+J35+K35+I35 -> 76397
A36: Ohio | B36: 204988 | C36: 1132.42 | D36: =C36*12 -> 13589.04 | E36: 590 | F36: =E36*12 -> 7080 | G36: =1412.74*12 -> 16952.88 | H36: 9600 | I36: 37306 | J36: 1306 | K36: 1769 | L36: =G36+F36+D36+J36+K36+I36 -> 78002.92
A37: Oklahoma | B37: 197204 | C37: 1089.42 | D37: =C37*12 -> 13073.04 | E37: 522 | F37: =E37*12 -> 6264 | G37: =1398.02*12 -> 16776.24 | H37: 9600 | I37: 34810 | J37: 1310 | K37: 1775 | L37: =G37+F37+D37+J37+K37+I37 -> 74008.28
A38: Oregon | B38: 467854 | C38: 2584.57 | D38: =C38*12 -> 31014.84 | E38: 628 | F38: =E38*12 -> 7536 | G38: =1530.46*12 -> 18365.52 | H38: 9600 | I38: 42714 | J38: 1406 | K38: 1877 | L38: =G38+F38+D38+J38+K38+I38 -> 102913.36
A39: Pennsylvania | B39: 246367 | C39: 1361.01 | D39: =C39*12 -> 16332.12 | E39: 514 | F39: =E39*12 -> 6168 | G39: =1471.6*12 -> 17659.2 | H39: 9600 | I39: 41341 | J39: 1313 | K39: 1775 | L39: =G39+F39+D39+J39+K39+I39 -> 84588.32
A40: Rhode Island | B40: 432623 | C40: 2389.94 | D40: =C40*12 -> 28679.28 | E40: 561 | F40: =E40*12 -> 6732 | G40: =1515.75*12 -> 18189 | H40: 9600 | I40: 42214 | J40: 1353 | K40: 1825 | L40: =G40+F40+D40+J40+K40+I40 -> 98992.28
...

Sheet fact_metrics
A1: State | B1: School Score | C1: Violent Crime Rate per 100k (VCR)
A2: Alabama | B2: 240.25 | C2: 359.9
A3: Alaska | B3: 234.5 | C3: 724.1
A4: Arizona | B4: 241 | C4: 421.9
A5: Arkansas | B5: 240.25 | C5: 579.4
A6: California | B6: 242 | C6: 486
A7: Colorado | B7: 250.75 | C7: 476.3
A8: Connecticut | B8: 249.5 | C8: 136
A9: Delaware | B9: 238.75 | C9: 360.8
A10: Florida | B10: 245.25 | C10: 267.1
A11: Georgia | B11: 244.5 | C11: 325.7
A12: Hawaii | B12: 245.5 | C12: 217.7
A13: Idaho | B13: 248.25 | C13: 230.6
... A51: Wyoming | B51: 250.75 | C51: 203.4

Sheet ref_national
B1: cost per child | C1: average house price | D1: monthly payment | E1: yearly payment | F1: Utility / mo | G1: utility / year | H1: groceries / year | I1: cat / year | J1: dog / year | K1: house and expenses | L1: school score | M1: crime rate
B2: =average(fact_costs!I2:I51) -> 37151.06 | C2: =AVERAGE(fact_costs!B2:B51) -> 343123.92 | D2: =AVERAGE(fact_costs!C2:C51) -> 1895.523 | E2: =D2*12 -> 22746.276 | F2: 594 | G2: =F2*12 -> 7128 | H2: =12*1339.52 -> 16074.24 | I2: =average(fact_costs!J2:J52) -> 1350.72 | J2: =average(fact_costs!K2:K52) -> 1819.9 | K2: =H2+G2+E2+I2+J2+B2 -> 86270.196 | L2: 246 | M2: 327.6
A5: standard deviations | B5: =STDEV(fact_costs!I2:I51) -> 6022.8519 | C5: =STDEV(fact_costs!B2:B51) -> 139267.75 | D5: =STDEV(fact_costs!C2:C51) -> 769.35816 | E5: =STDEV(fact_costs!D2:D51) -> 9232.2979 | F5: =STDEV(fact_costs!E2:E51) -> 63.478822 | G5: =STDEV(fact_costs!F2:F51) -> 761.74586 | H5: =STDEV(fact_costs!G2:G51) -> 1195.7062 | I5: =STDEV(fact_costs!J2:J51) -> 36.385151 | J5: =STDEV(fact_costs!K2:K51) -> 39.255963 | K5: =STDEV(fact_costs!L2:L51) -> 14940.63 | L5: =STDEV(fact_metrics!B2:B51) -> 4.6788604 | M5: =STDEV(fact_metrics!C2:C51) -> 139.64991

Sheet zscores
A1: mean | B1: 246 | C1: 327.6 | D1: 86462.196
A2: stdev | B2: 4.6788604 | C2: 139.64991 | D2: =stdev(fact_costs!L2:L51) -> 14940.63
A4: state | B4: school z score | C4: vcr z score | D4: house and expenses | E4: composite | F4: composite school weighted | G4: composite cost weighted
A5: New Hampshire | B5: =(fact_metrics!B30-$B$1)/$B$2 -> 1.2289317 | C5: =-(fact_metrics!C30-$C$1)/$C$2 -> 1.5574661 | D5: =-(fact_costs!L30-$D$1)/$D$2 -> -0.94835654 | E5: =average(B5:D5) -> 0.61268041 | F5: =AVERAGE((B5*0.5)+(C5*0.4)+(D5*0.1)) -> 1.1426166 | G5: =AVERAGE((D5*0.5)+(B5*0.3)+(C5*0.2)) -> 0.20599446
A6: Wyoming | B6: =(fact_metrics!B51-$B$1)/$B$2 -> 1.0152045 | C6: =-(fact_metrics!C51-$C$1)/$C$2 -> 0.88936682 | D6: =-(fact_costs!L51-$D$1)/$D$2 -> 0.31807736 | E6: =average(B6:D6) -> 0.74088288 | F6: =AVERAGE((B6*0.5)+(C6*0.4)+(D6*0.1)) -> 0.8951567 | G6: =AVERAGE((D6*0.5)+(B6*0.3)+(C6*0.2)) -> 0.64147338
A7: New Jersey | B7: =(fact_metrics!B31-$B$1)/$B$2 -> 1.3892272 | C7: =-(fact_metrics!C31-$C$1)/$C$2 -> 0.78696791 | D7: =-(fact_costs!L31-$D$1)/$D$2 -> -1.2397231 | E7: =average(B7:D7) -> 0.31215732 | F7: =AVERAGE((B7*0.5)+(C7*0.4)+(D7*0.1)) -> 0.88542844 | G7: =AVERAGE((D7*0.5)+(B7*0.3)+(C7*0.2)) -> -0.045699823
A8: Massachusetts | B8: =(fact_metrics!B22-$B$1)/$B$2 -> 2.0304089 | C8: =-(fact_metrics!C22-$C$1)/$C$2 -> 0.092373849 | D8: =-(fact_costs!L22-$D$1)/$D$2 -> -2.2146137 | E8: =average(B8:D8) -> -0.030610318 | F8: =AVERAGE((B8*0.5)+(C8*0.4)+(D8*0.1)) -> 0.83069264 | G8: =AVERAGE((D8*0.5)+(B8*0.3)+(C8*0.2)) -> -0.47970942
A9: Connecticut | B9: =(fact_metrics!B8-$B$1)/$B$2 -> 0.7480454 | C9: =-(fact_metrics!C8-$C$1)/$C$2 -> 1.3720023 | D9: =-(fact_costs!L8-$D$1)/$D$2 -> -1.1796962 | E9: =average(B9:D9) -> 0.3134505 | F9: =AVERAGE((B9*0.5)+(C9*0.4)+(D9*0.1)) -> 0.80485399 | G9: =AVERAGE((D9*0.5)+(B9*0.3)+(C9*0.2)) -> -0.091034019
A10: Utah | B10: =(fact_metrics!B45-$B$1)/$B$2 -> 1.0686363 | C10: =-(fact_metrics!C45-$C$1)/$C$2 -> 0.70175482 | D10: =-(fact_costs!L45-$D$1)/$D$2 -> -0.51527172 | E10: =average(B10:D10) -> 0.41837313 | F10: =AVERAGE((B10*0.5)+(C10*0.4)+(D10*0.1)) -> 0.7634929 | G10: =AVERAGE((D10*0.5)+(B10*0.3)+(C10*0.2)) -> 0.20330599
A11: North Dakota | B11: =(fact_metrics!B35-$B$1)/$B$2 -> 0.53431814 | C11: =-(fact_metrics!C35-$C$1)/$C$2 -> 0.52488396 | D11: =-(fact_costs!L35-$D$1)/$D$2 -> 0.6736795 | E11: =average(B11:D11) -> 0.5776272 | F11: =AVERAGE((B11*0.5)+(C11*0.4)+(D11*0.1)) -> 0.54448061 | G11: =AVERAGE((D11*0.5)+(B11*0.3)+(C11*0.2)) -> 0.60211199
A12: Minnesota | B12: =(fact_metrics!B24-$B$1)/$B$2 -> 0.69461359 | C12: =-(fact_metrics!C24-$C$1)/$C$2 -> 0.50841421 | D12: =-(fact_costs!L24-$D$1)/$D$2 -> -0.23570385 | E12: =average(B12:D12) -> 0.32244131 | F12: =AVERAGE((B12*0.5)+(C12*0.4)+(D12*0.1)) -> 0.52710209 | G12: =AVERAGE((D12*0.5)+(B12*0.3)+(C12*0.2)) -> 0.19221499
A13: Indiana | B13: =(fact_metrics!B15-$B$1)/$B$2 -> 0.85490903 | C13: =-(fact_metrics!C15-$C$1)/$C$2 -> 0.10526322 | D13: =-(fact_costs!L15-$D$1)/$D$2 -> 0.51062346 | E13: =average(B13:D13) -> 0.49026524 | F13: =AVERAGE((B13*0.5)+(C13*0.4)+(D13*0.1)) -> 0.52062215 | G13: =AVERAGE((D13*0.5)+(B13*0.3)+(C13*0.2)) -> 0.53283708
A14: Wisconsin | B14: =(fact_metrics!B50-$B$1)/$B$2 -> 0.69461359 | C14: =-(fact_metrics!C50-$C$1)/$C$2 -> 0.35159349 | D14: =-(fact_costs!L50-$D$1)/$D$2 -> 0.29192585 | E14: =average(B14:D14) -> 0.44604431 | F14: =AVERAGE((B14*0.5)+(C14*0.4)+(D14*0.1)) -> 0.51713677 | G14: =AVERAGE((D14*0.5)+(B14*0.3)+(C14*0.2)) -> 0.4246657
A15: Idaho | B15: =(fact_metrics!B13-$B$1)/$B$2 -> 0.48088633 | C15: =-(fact_metrics!C13-$C$1)/$C$2 -> 0.69459406 | D15: =-(fact_costs!L13-$D$1)/$D$2 -> -0.16415667 | E15: =average(B15:D15) -> 0.33710791 | F15: =AVERAGE((B15*0.5)+(C15*0.4)+(D15*0.1)) -> 0.50186512 | G15: =AVERAGE((D15*0.5)+(B15*0.3)+(C15*0.2)) -> 0.20110638
A16: Kentucky | B16: =(fact_metrics!B18-$B$1)/$B$2 -> 0.053431814 | C16: =-(fact_metrics!C18-$C$1)/$C$2 -> 0.81990742 | D16: =-(fact_costs!L18-$D$1)/$D$2 -> 1.034422 | E16: =average(B16:D16) -> 0.63592041 | F16: =AVERAGE((B16*0.5)+(C16*0.4)+(D16*0.1)) -> 0.45812107 | G16: =AVERAGE((D16*0.5)+(B16*0.3)+(C16*0.2)) -> 0.69722202
A17: Iowa | B17: =(fact_metrics!B16-$B$1)/$B$2 -> 0.21372726 | C17: =-(fact_metrics!C16-$C$1)/$C$2 -> 0.60365236 | D17: =-(fact_costs!L16-$D$1)/$D$2 -> 0.98111233 | E17: =average(B17:D17) -> 0.59949731 | F17: =AVERAGE((B17*0.5)+(C17*0.4)+(D17*0.1)) -> 0.44643581 | G17: =AVERAGE((D17*0.5)+(B17*0.3)+(C17*0.2)) -> 0.67540481
A18: Ohio | B18: =(fact_metrics!B36-$B$1)/$B$2 -> 0.53431814 | C18: =-(fact_metrics!C36-$C$1)/$C$2 -> 0.24274988 | D18: =-(fact_costs!L36-$D$1)/$D$2 -> 0.56619273 | E18: =average(B18:D18) -> 0.44775359 | F18: =AVERAGE((B18*0.5)+(C18*0.4)+(D18*0.1)) -> 0.4208783 | G18: =AVERAGE((D18*0.5)+(B18*0.3)+(C18*0.2)) -> 0.49194179
A19: Nebraska | B19: =(fact_metrics!B28-$B$1)/$B$2 -> 0.10686363 | C19: =-(fact_metrics!C28-$C$1)/$C$2 -> 0.76691777 | D19: =-(fact_costs!L28-$D$1)/$D$2 -> 0.54957764 | E19: =average(B19:D19) -> 0.47445301 | F19: =AVERAGE((B19*0.5)+(C19*0.4)+(D19*0.1)) -> 0.41515669 | G19: =AVERAGE((D19*0.5)+(B19*0.3)+(C19*0.2)) -> 0.46023146
A20: Pennsylvania | B20: =(fact_metrics!B39-$B$1)/$B$2 -> 0.26715907 | C20: =-(fact_metrics!C39-$C$1)/$C$2 -> 0.58718261 | D20: =-(fact_costs!L39-$D$1)/$D$2 -> 0.12542149 | E20: =average(B20:D20) -> 0.32658772 | F20: =AVERAGE((B20*0.5)+(C20*0.4)+(D20*0.1)) -> 0.38099473 | G20: =AVERAGE((D20*0.5)+(B20*0.3)+(C20*0.2)) -> 0.26029499
A21: Mississippi | B21: =(fact_metrics!B25-$B$1)/$B$2 -> -0.21372726 | C21: =-(fact_metrics!C25-$C$1)/$C$2 -> 0.8385254 | D21: =-(fact_costs!L25-$D$1)/$D$2 -> 1.2966064 | E21: =average(B21:D21) -> 0.64046818 | F21: =AVERAGE((B21*0.5)+(C21*0.4)+(D21*0.1)) -> 0.35820717 | G21: =AVERAGE((D21*0.5)+(B21*0.3)+(C21*0.2)) -> 0.7518901
A22: Rhode Island | B22: =(fact_metrics!B40-$B$1)/$B$2 -> -0.16029544 | C22: =-(fact_metrics!C40-$C$1)/$C$2 -> 1.2459728 | D22: =-(fact_costs!L40-$D$1)/$D$2 -> -0.83865836 | E22: =average(B22:D22) -> 0.082339682 | F22: =AVERAGE((B22*0.5)+(C22*0.4)+(D22*0.1)) -> 0.33437558 | G22: =AVERAGE((D22*0.5)+(B22*0.3)+(C22*0.2)) -> -0.21822324
A23: Illinois | B23: =(fact_metrics!B14-$B$1)/$B$2 -> 0.26715907 | C23: =-(fact_metrics!C14-$C$1)/$C$2 -> 0.27497332 | D23: =-(fact_costs!L14-$D$1)/$D$2 -> 0.44419788 | E23: =average(B23:D23) -> 0.32877675 | F23: =AVERAGE((B23*0.5)+(C23*0.4)+(D23*0.1)) -> 0.28798865 | G23: =AVERAGE((D23*0.5)+(B23*0.3)+(C23*0.2)) -> 0.35724132
A24: Virginia | B24: =(fact_metrics!B47-$B$1)/$B$2 -> -0.053431814 | C24: =-(fact_metrics!C47-$C$1)/$C$2 -> 0.78553575 | D24: =-(fact_costs!L47-$D$1)/$D$2 -> -0.074800328 | E24: =average(B24:D24) -> 0.2191012 | F24: =AVERAGE((B24*0.5)+(C24*0.4)+(D24*0.1)) -> 0.28001836 | G24: =AVERAGE((D24*0.5)+(B24*0.3)+(C24*0.2)) -> 0.10367744
A25: South Dakota | B25: =(fact_metrics!B42-$B$1)/$B$2 -> 0.58774996 | C25: =-(fact_metrics!C42-$C$1)/$C$2 -> -0.24847849 | D25: =-(fact_costs!L42-$D$1)/$D$2 -> 0.76465826 | E25: =average(B25:D25) -> 0.36797658 | F25: =AVERAGE((B25*0.5)+(C25*0.4)+(D25*0.1)) -> 0.27094941 | G25: =AVERAGE((D25*0.5)+(B25*0.3)+(C25*0.2)) -> 0.50895842
A26: Maine | B26: =(fact_metrics!B20-$B$1)/$B$2 -> -0.69461359 | C26: =-(fact_metrics!C20-$C$1)/$C$2 -> 1.6290737 | D26: =-(fact_costs!L20-$D$1)/$D$2 -> -0.39844934 | E26: =average(B26:D26) -> 0.17867026 | F26: =AVERAGE((B26*0.5)+(C26*0.4)+(D26*0.1)) -> 0.26447775 | G26: =AVERAGE((D26*0.5)+(B26*0.3)+(C26*0.2)) -> -0.081794005
A27: Vermont | B27: =(fact_metrics!B46-$B$1)/$B$2 -> -0.16029544 | C27: =-(fact_metrics!C46-$C$1)/$C$2 -> 0.77694284 | D27: =-(fact_costs!L46-$D$1)/$D$2 -> -1.0499507 | E27: =average(B27:D27) -> -0.14443442 | F27: =AVERAGE((B27*0.5)+(C27*0.4)+(D27*0.1)) -> 0.12563435 | G27: =AVERAGE((D27*0.5)+(B27*0.3)+(C27*0.2)) -> -0.41767539
A28: Florida | B28: =(fact_metrics!B10-$B$1)/$B$2 -> -0.16029544 | C28: =-(fact_metrics!C10-$C$1)/$C$2 -> 0.43322619 | D28: =-(fact_costs!L10-$D$1)/$D$2 -> 0.034547138 | E28: =average(B28:D28) -> 0.10249263 | F28: =AVERAGE((B28*0.5)+(C28*0.4)+(D28*0.1)) -> 0.096597469 | G28: =AVERAGE((D28*0.5)+(B28*0.3)+(C28*0.2)) -> 0.055830174
A29: Colorado | B29: =(fact_metrics!B7-$B$1)/$B$2 -> 1.0152045 | C29: =-(fact_metrics!C7-$C$1)/$C$2 -> -1.0648055 | D29: =-(fact_costs!L7-$D$1)/$D$2 -> -1.2516932 | E29: =average(B29:D29) -> -0.43376474 | F29: =AVERAGE((B29*0.5)+(C29*0.4)+(D29*0.1)) -> -0.043489292 | G29: =AVERAGE((D29*0.5)+(B29*0.3)+(C29*0.2)) -> -0.53424634
A30: Montana | B30: =(fact_metrics!B27-$B$1)/$B$2 -> 0.58774996 | C30: =-(fact_metrics!C27-$C$1)/$C$2 -> -0.68671722 | D30: =-(fact_costs!L27-$D$1)/$D$2 -> -0.62885194 | E30: =average(B30:D30) -> -0.2426064 | F30: =AVERAGE((B30*0.5)+(C30*0.4)+(D30*0.1)) -> -0.043697103 | G30: =AVERAGE((D30*0.5)+(B30*0.3)+(C30*0.2)) -> -0.27544443
A31: Hawaii | B31: =(fact_metrics!B12-$B$1)/$B$2 -> -0.10686363 | C31: =-(fact_metrics!C12-$C$1)/$C$2 -> 0.78696791 | D31: =-(fact_costs!L12-$D$1)/$D$2 -> -3.2821189 | E31: =average(B31:D31) -> -0.86733822 | F31: =AVERAGE((B31*0.5)+(C31*0.4)+(D31*0.1)) -> -0.066856546 | G31: =AVERAGE((D31*0.5)+(B31*0.3)+(C31*0.2)) -> -1.515725
A32: Washington | B32: =(fact_metrics!B48-$B$1)/$B$2 -> 0.16029544 | C32: =-(fact_metrics!C48-$C$1)/$C$2 -> 0.010741145 | D32: =-(fact_costs!L48-$D$1)/$D$2 -> -1.5606868 | E32: =average(B32:D32) -> -0.46321675 | F32: =AVERAGE((B32*0.5)+(C32*0.4)+(D32*0.1)) -> -0.071624503 | G32: =AVERAGE((D32*0.5)+(B32*0.3)+(C32*0.2)) -> -0.73010655
A33: Georgia | B33: =(fact_metrics!B11-$B$1)/$B$2 -> -0.32059089 | C33: =-(fact_metrics!C11-$C$1)/$C$2 -> 0.013605451 | D33: =-(fact_costs!L11-$D$1)/$D$2 -> 0.64320421 | E33: =average(B33:D33) -> 0.11207293 | F33: =AVERAGE((B33*0.5)+(C33*0.4)+(D33*0.1)) -> -0.090532841 | G33: =AVERAGE((D33*0.5)+(B33*0.3)+(C33*0.2)) -> 0.22814593
A34: North Carolina | B34: =(fact_metrics!B34-$B$1)/$B$2 -> -0.053431814 | C34: =-(fact_metrics!C34-$C$1)/$C$2 -> -0.3451488 | D34: =-(fact_costs!L34-$D$1)/$D$2 -> 0.4717844 | E34: =average(B34:D34) -> 0.024401261 | F34: =AVERAGE((B34*0.5)+(C34*0.4)+(D34*0.1)) -> -0.11759699 | G34: =AVERAGE((D34*0.5)+(B34*0.3)+(C34*0.2)) -> 0.15083289
A35: Kansas | B35: =(fact_metrics!B17-$B$1)/$B$2 -> -0.26715907 | C35: =-(fact_metrics!C17-$C$1)/$C$2 -> -0.79556082 | D35: =-(fact_costs!L17-$D$1)/$D$2 -> 0.99068086 | E35: =average(B35:D35) -> -0.02401301 | F35: =AVERAGE((B35*0.5)+(C35*0.4)+(D35*0.1)) -> -0.35273578 | G35: =AVERAGE((D35*0.5)+(B35*0.3)+(C35*0.2)) -> 0.25608055
A36: New York | B36: =(fact_metrics!B33-$B$1)/$B$2 -> -0.3740227 | C36: =-(fact_metrics!C33-$C$1)/$C$2 -> -0.37665616 | D36: =-(fact_costs!L33-$D$1)/$D$2 -> -0.35415134 | E36: =average(B36:D36) -> -0.36827673 | F36: =AVERAGE((B36*0.5)+(C36*0.4)+(D36*0.1)) -> -0.37308895 | G36: =AVERAGE((D36*0.5)+(B36*0.3)+(C36*0.2)) -> -0.36461371
A37: Texas | B37: =(fact_metrics!B44-$B$1)/$B$2 -> -0.53431814 | C37: =-(fact_metrics!C44-$C$1)/$C$2 -> -0.44253518 | D37: =-(fact_costs!L44-$D$1)/$D$2 -> 0.58849434 | E37: =average(B37:D37) -> -0.129453 | F37: =AVERAGE((B37*0.5)+(C37*0.4)+(D37*0.1)) -> -0.38532371 | G37: =AVERAGE((D37*0.5)+(B37*0.3)+(C37*0.2)) -> 0.045444689
A38: South Carolina | B38: =(fact_metrics!B41-$B$1)/$B$2 -> -0.48088633 | C38: =-(fact_metrics!C41-$C$1)/$C$2 -> -0.7812393 | D38: =-(fact_costs!L41-$D$1)/$D$2 -> 0.59917662 | E38: =average(B38:D38) -> -0.220983 | F38: =AVERAGE((B38*0.5)+(C38*0.4)+(D38*0.1)) -> -0.49302122 | G38: =AVERAGE((D38*0.5)+(B38*0.3)+(C38*0.2)) -> -0.00092544877
A39: Maryland | B39: =(fact_metrics!B21-$B$1)/$B$2 -> -0.42745451 | C39: =-(fact_metrics!C21-$C$1)/$C$2 -> -0.66451885 | D39: =-(fact_costs!L21-$D$1)/$D$2 -> -0.43194725 | E39: =average(B39:D39) -> -0.50797354 | F39: =AVERAGE((B39*0.5)+(C39*0.4)+(D39*0.1)) -> -0.52272952 | G39: =AVERAGE((D39*0.5)+(B39*0.3)+(C39*0.2)) -> -0.47711375
A40: Tennessee | B40: =(fact_metrics!B43-$B$1)/$B$2 -> 0.32059089 | C40: =-(fact_metrics!C43-$C$1)/$C$2 -> -1.8954541 | D40: =-(fact_costs!L43-$D$1)/$D$2 -> 0.548405 | E40: =average(B40:D40) -> -0.34215274 | F40: =AVERAGE((B40*0.5)+(C40*0.4)+(D40*0.1)) -> -0.54304569 | G40: =AVERAGE((D40*0.5)+(B40*0.3)+(C40*0.2)) -> -0.008711055
A41: Alabama | B41: =(fact_metrics!B2-$B$1)/$B$2 -> -1.2289317 | C41: =-(fact_metrics!C2-$C$1)/$C$2 -> -0.23129266 | D41: =-(fact_costs!L2-$D$1)/$D$2 -> 1.0285641 | E41: =average(B41:D41) -> -0.14388675 | F41: =AVERAGE((B41*0.5)+(C41*0.4)+(D41*0.1)) -> -0.60412651 | G41: =AVERAGE((D41*0.5)+(B41*0.3)+(C41*0.2)) -> 0.09934402
...
